<?xml version='1.0'?>
<sdf version='1.7'>
  <model name='simple_manipulator6'>
  
    <include>
      <uri>model://vacuum_gripper</uri>
      <pose>0.35 0 0.07 0 -0 0</pose>
    </include>
 
     <include>
      <uri>model://riser</uri>
      <pose>0.7 0 0.017 0 0 0</pose>
    </include>
   
    <include>
      <uri>model://my_simple_arm</uri>
      <pose>0 0 0 0 0 0</pose>
    </include>

    
    <joint name="forearm_arm_joint" type="prismatic">
      <parent>simple_arm::forearm</parent>
      <child>riser::arm</child>
      <axis>
                <limit>
                    <lower>0</lower>
                    <upper>0.3</upper>
                </limit>
                <xyz>0 0 1</xyz>
            </axis>
    </joint>
   
    <joint name="riser_gripper_joint" type="revolute">
      <parent>riser::arm</parent>
      <child>vacuum_gripper::link_0</child>
      <origin rpy="0 0 0" xyz="0 0 0" />
      <limit effort="0" velocity="0.0001" lower="0" upper="0" />
    </joint>
    
    <plugin name="gazebo_ros_vacuum_gripper" filename="libgazebo_ros_vacuum_gripper.so">
        <robotNamespace>/robot/left_vacuum_gripper</robotNamespace>
        <bodyName>vacuum_gripper::link_0</bodyName>
        <topicName>grasping</topicName>
     </plugin>
    
  </model>
</sdf>

