<?xml version='1.0'?>
<sdf version='1.5'>
  <model name="simple_arm_w_riser">

   <include>
      <uri>model://riser</uri>
      <pose>0.7 0 0.017 0 0 0</pose>
    </include>

    <include>
      <uri>model://my_simple_arm</uri>
      <pose>0 0 0 0 0 0</pose>
    </include>

    <joint name="forearm_arm_joint" type="prismatic">
      <parent>simple_arm::forearm</parent>
      <child>riser::arm</child>
      <axis>
                <limit>
                    <lower>0</lower>
                    <upper>0.3</upper>
                </limit>
                <xyz>0 0 1</xyz>
            </axis>
    </joint>
    
   
  </model>
 </sdf>
